Workbook

Sheet Forecast
A1: Revenue Forecast: March 2021 to February 2022
A2: Forecast = seasonal index * deseasonalized level * (1 + monthly growth)^n
A3: Upper Bound: | C3: 0.03 | E3: See Assumptions tab
A4: Lower Bound: | C4: -0.02 | E4: See Assumptions tab
A5: Forecast Base: | C5: 0 | E5: See Assumptions tab
A6: Deseasonalized level: | C6: =Seasonality!M22 -> 381339.14 | E6: See Seasonality tab
A8: Month | B8: n | C8: Seasonal Index | D8: Lower Bound (USD) | E8: Forecast (USD) | F8: Upper Bound (USD) | G8: Original Forecast * Scale factor | H8: Forecast - Original
A9: 44256 | B9: 1 | C9: =INDEX(Seasonality!$O$8:$O$19,MONTH(Forecast!A9)) -> 0.55770218 | D9: =C9*$C$6*(1+$C$4)^B9 -> 208420.2 | E9: =C9*$C$6*(1+$C$5)^B9 -> 212673.67 | F9: =C9*$C$6*(1+$C$3)^B9 -> 219053.88 | G9: ='Forecast Sheet'!C82 -> 763877.37 | H9: =E9-G9 -> -551203.7
A10: 44287 | B10: =B9+1 -> 2 | C10: =INDEX(Seasonality!$O$8:$O$19,MONTH(Forecast!A10)) -> 0.093836862 | D10: =C10*$C$6*(1+$C$4)^B10 -> 34366.635 | E10: =C10*$C$6*(1+$C$5)^B10 -> 35783.668 | F10: =C10*$C$6*(1+$C$3)^B10 -> 37962.894 | G10: ='Forecast Sheet'!C83 -> 769844 | H10: =E10-G10 -> -734060.33
A11: 44317 | B11: =B10+1 -> 3 | C11: =INDEX(Seasonality!$O$8:$O$19,MONTH(Forecast!A11)) -> 1.0827929 | D11: =C11*$C$6*(1+$C$4)^B11 -> 388628.82 | E11: =C11*$C$6*(1+$C$5)^B11 -> 412911.31 | F11: =C11*$C$6*(1+$C$3)^B11 -> 451199.34 | G11: ='Forecast Sheet'!C84 -> 775810.63 | H11: =E11-G11 -> -362899.32
A12: 44348 | B12: =B11+1 -> 4 | C12: =INDEX(Seasonality!$O$8:$O$19,MONTH(Forecast!A12)) -> 0.97911466 | D12: =C12*$C$6*(1+$C$4)^B12 -> 344388.98 | E12: =C12*$C$6*(1+$C$5)^B12 -> 373374.74 | F12: =C12*$C$6*(1+$C$3)^B12 -> 420236.56 | G12: ='Forecast Sheet'!C85 -> 781777.27 | H12: =E12-G12 -> -408402.52
A13: 44378 | B13: =B12+1 -> 5 | C13: =INDEX(Seasonality!$O$8:$O$19,MONTH(Forecast!A13)) -> 0.85333255 | D13: =C13*$C$6*(1+$C$4)^B13 -> 294144.05 | E13: =C13*$C$6*(1+$C$5)^B13 -> 325409.1 | F13: =C13*$C$6*(1+$C$3)^B13 -> 377238.34 | G13: ='Forecast Sheet'!C86 -> 787743.9 | H13: =E13-G13 -> -462334.8
A14: 44409 | B14: =B13+1 -> 6 | C14: =INDEX(Seasonality!$O$8:$O$19,MONTH(Forecast!A14)) -> 0.91092865 | D14: =C14*$C$6*(1+$C$4)^B14 -> 307717.5 | E14: =C14*$C$6*(1+$C$5)^B14 -> 347372.75 | F14: =C14*$C$6*(1+$C$3)^B14 -> 414781.23 | G14: ='Forecast Sheet'!C87 -> 793710.53 | H14: =E14-G14 -> -446337.78
A15: 44440 | B15: =B14+1 -> 7 | C15: =INDEX(Seasonality!$O$8:$O$19,MONTH(Forecast!A15)) -> 0.98927759 | D15: =C15*$C$6*(1+$C$4)^B15 -> 327500.59 | E15: =C15*$C$6*(1+$C$5)^B15 -> 377250.27 | F15: =C15*$C$6*(1+$C$3)^B15 -> 463970.24 | G15: ='Forecast Sheet'!C88 -> 799677.16 | H15: =E15-G15 -> -422426.9
A16: 44470 | B16: =B15+1 -> 8 | C16: =INDEX(Seasonality!$O$8:$O$19,MONTH(Forecast!A16)) -> 1.004943 | D16: =C16*$C$6*(1+$C$4)^B16 -> 326032.88 | E16: =C16*$C$6*(1+$C$5)^B16 -> 383224.09 | F16: =C16*$C$6*(1+$C$3)^B16 -> 485456.81 | G16: ='Forecast Sheet'!C89 -> 805643.79 | H16: =E16-G16 -> -422419.71
A17: 44501 | B17: =B16+1 -> 9 | C17: =INDEX(Seasonality!$O$8:$O$19,MONTH(Forecast!A17)) -> 1.081312 | D17: =C17*$C$6*(1+$C$4)^B17 -> 343793.04 | E17: =C17*$C$6*(1+$C$5)^B17 -> 412346.59 | F17: =C17*$C$6*(1+$C$3)^B17 -> 538018.77 | G17: ='Forecast Sheet'!C90 -> 811610.43 | H17: =E17-G17 -> -399263.84
A18: 44531 | B18: =B17+1 -> 10 | C18: =INDEX(Seasonality!$O$8:$O$19,MONTH(Forecast!A18)) -> 1.6935273 | D18: =C18*$C$6*(1+$C$4)^B18 -> 527672.36 | E18: =C18*$C$6*(1+$C$5)^B18 -> 645808.25 | F18: =C18*$C$6*(1+$C$3)^B18 -> 867912.28 | G18: ='Forecast Sheet'!C91 -> 817577.06 | H18: =E18-G18 -> -171768.81
A19: 44562 | B19: =B18+1 -> 11 | C19: =INDEX(Seasonality!$O$8:$O$19,MONTH(Forecast!A19)) -> 1.2634176 | D19: =C19*$C$6*(1+$C$4)^B19 -> 385784.81 | E19: =C19*$C$6*(1+$C$5)^B19 -> 481790.57 | F19: =C19*$C$6*(1+$C$3)^B19 -> 666910.82 | G19: ='Forecast Sheet'!C92 -> 823543.69 | H19: =E19-G19 -> -341753.12
A20: 44593 | B20: =B19+1 -> 12 | C20: =INDEX(Seasonality!$O$8:$O$19,MONTH(Forecast!A20)) -> 1.4898148 | D20: =C20*$C$6*(1+$C$4)^B20 -> 445816.95 | E20: =C20*$C$6*(1+$C$5)^B20 -> 568124.69 | F20: =C20*$C$6*(1+$C$3)^B20 -> 810009.96 | G20: ='Forecast Sheet'!C93 -> 829510.32 | H20: =E20-G20 -> -261385.63
A21: Total: | D21: =SUM(D9:D20) -> 3934266.8 | E21: =SUM(E9:E20) -> 4576069.7 | F21: =SUM(F9:F20) -> 5752751.1 | G21: =SUM(G9:G20) -> 9560326.2 | H21: =SUM(H9:H20) -> -4984256.5
A25: Chart: March 2019 to February 2022
A26: Timeline | B26: Values (USD) | C26: Forecast (USD) | D26: Lower Bound (USD) | E26: Upper Bound (USD)
A27: =Data!A43 -> 43525 | B27: =Data!C43 -> 845925.09
A28: =Data!A44 -> 43556 | B28: =Data!C44 -> 149892.71
A29: =Data!A45 -> 43586 | B29: =Data!C45 -> 1594446.5
A30: =Data!A46 -> 43617 | B30: =Data!C46 -> 1404861.4
A31: =Data!A47 -> 43647 | B31: =Data!C47 -> 1408714.6
A32: =Data!A48 -> 43678 | B32: =Data!C48 -> 1500784.8
A33: =Data!A49 -> 43709 | B33: =Data!C49 -> 1547870.7
A34: =Data!A50 -> 43739 | B34: =Data!C50 -> 1575168.8
A35: =Data!A51 -> 43770 | B35: =Data!C51 -> 1715659.9
A36: =Data!A52 -> 43800 | B36: =Data!C52 -> 2477295.9
A37: =Data!A53 -> 43831 | B37: =Data!C53 -> 2068951.1
A38: =Data!A54 -> 43862 | B38: =Data!C54 -> 2227379.6
... A49: =Data!A65 -> 44197 | B49: =Data!C65 -> 513021.58
A50: =Data!A66 -> 44228 | B50: =Data!$C$66 -> 526266.9 | C50: =Data!$C$66 -> 526266.9 | D50: =Data!$C$66 -> 526266.9 | E50: =Data!$C$66 -> 526266.9
A51: =A9 -> 44256 | C51: =E9 -> 212673.67 | D51: =D9 -> 208420.2 | E51: =F9 -> 219053.88
A52: =A10 -> 44287 | C52: =E10 -> 35783.668 | D52: =D10 -> 34366.635 | E52: =F10 -> 37962.894
A53: =A11 -> 44317 | C53: =E11 -> 412911.31 | D53: =D11 -> 388628.82 | E53: =F11 -> 451199.34
A54: =A12 -> 44348 | C54: =E12 -> 373374.74 | D54: =D12 -> 344388.98 | E54: =F12 -> 420236.56
...

Sheet Assumptions
A1: Assumptions:
A3: 1. The last month used to estimate indeces is July 2019, so that no 2020 data enters the seasonal trend.
A4: 2. The current revenue level is estimated as the average of the last 3 deseasonalized months, that is December 2020, January 2021, and February 2021.
A5: 3. The growth rate returns to its pace similar to the year 2019, that is +3% a month.
A6: 4. The 2020 declines continues at a milder rate than 2020, that is -2% a month. A steeper decline can also be considered.
A7: 5. The deseasonalized level persists (average of the last 3 months), with no recovery nor further decline.
A8: 6. The 2016-2019 seasonal patterns still hold.

Sheet Seasonality
A1: Seasonal Model
A2: Seasonal Index = average of (revenue / centered 12-month average) for each calendar month.
A3: Assumptions: | B3: Last month used to estimate seasonal indices | E3: 43647 | G3: Last k months: | H3: 3
A4: Month | B4: Revenue | C4: Month Number | D4: Centered 12-Month Average | E4: Percentage | F4: Seasonal Index | G4: Deseasonalized Revenue
A5: 42370 | B5: 649918.78 | C5: =MONTH(A5) -> 1 | F5: =INDEX($O$8:$O$19, C5) -> 1.2634176 | G5: =B5/F5 -> 514413.29
A6: 42401 | B6: 891098.3 | C6: =MONTH(A6) -> 2 | F6: =INDEX($O$8:$O$19, C6) -> 1.4898148 | G6: =B6/F6 -> 598126.9
A7: 42430 | B7: 338407.36 | C7: =MONTH(A7) -> 3 | F7: =INDEX($O$8:$O$19, C7) -> 0.55770218 | G7: =B7/F7 -> 606788.66 | K7: Month Number | L7: Month | M7: Ratios Used | N7: Seasonal Ratio | O7: Seasonal Index
A8: 42461 | B8: 110591.63 | C8: =MONTH(A8) -> 4 | F8: =INDEX($O$8:$O$19, C8) -> 0.093836862 | G8: =B8/F8 -> 1178552.1 | K8: 1 | L8: Jan | M8: =COUNTIFS(C5:C66,K8,A5:A66,"<=" & $E$3, E5:E66, ">0") -> 3 | N8: =AVERAGEIFS(E5:E66,C5:C66,K8,A5:A66,"<=" & $E$3) -> 1.2551215 | O8: =N8/AVERAGE($N$8:$N$19) -> 1.2634176
A9: 42491 | B9: 595986.18 | C9: =MONTH(A9) -> 5 | F9: =INDEX($O$8:$O$19, C9) -> 1.0827929 | G9: =B9/F9 -> 550415.68 | K9: =K8+1 -> 2 | L9: Feb | M9: =COUNTIFS(C6:C67,K9,A6:A67,"<=" & $E$3, E6:E67, ">0") -> 3 | N9: =AVERAGEIFS(E6:E67,C6:C67,K9,A6:A67,"<=" & $E$3) -> 1.4800322 | O9: =N9/AVERAGE($N$8:$N$19) -> 1.4898148
A10: 42522 | B10: 518585.28 | C10: =MONTH(A10) -> 6 | F10: =INDEX($O$8:$O$19, C10) -> 0.97911466 | G10: =B10/F10 -> 529647.14 | K10: =K9+1 -> 3 | L10: Mar | M10: =COUNTIFS(C7:C68,K10,A7:A68,"<=" & $E$3, E7:E68, ">0") -> 3 | N10: =AVERAGEIFS(E7:E68,C7:C68,K10,A7:A68,"<=" & $E$3) -> 0.55404012 | O10: =N10/AVERAGE($N$8:$N$19) -> 0.55770218
A11: 42552 | B11: 454959.83 | C11: =MONTH(A11) -> 7 | D11: =(AVERAGE(B5:B16)+AVERAGE(B6:B17))/2 -> 579740.96 | E11: =B11/D11 -> 0.78476399 | F11: =INDEX($O$8:$O$19, C11) -> 0.85333255 | G11: =B11/F11 -> 533156.54 | K11: =K10+1 -> 4 | L11: Apr | M11: =COUNTIFS(C8:C69,K11,A8:A69,"<=" & $E$3, E8:E69, ">0") -> 3 | N11: =AVERAGEIFS(E8:E69,C8:C69,K11,A8:A69,"<=" & $E$3) -> 0.093220698 | O11: =N11/AVERAGE($N$8:$N$19) -> 0.093836862
A12: 42583 | B12: 547512.69 | C12: =MONTH(A12) -> 8 | D12: =(AVERAGE(B6:B17)+AVERAGE(B7:B18))/2 -> 574725.29 | E12: =B12/D12 -> 0.95265111 | F12: =INDEX($O$8:$O$19, C12) -> 0.91092865 | G12: =B12/F12 -> 601048.93 | K12: =K11+1 -> 5 | L12: May | M12: =COUNTIFS(C9:C70,K12,A9:A70,"<=" & $E$3, E9:E70, ">0") -> 3 | N12: =AVERAGEIFS(E9:E70,C9:C70,K12,A9:A70,"<=" & $E$3) -> 1.0756829 | O12: =N12/AVERAGE($N$8:$N$19) -> 1.0827929
A13: 42614 | B13: 567421.12 | C13: =MONTH(A13) -> 9 | D13: =(AVERAGE(B7:B18)+AVERAGE(B8:B19))/2 -> 568569.84 | E13: =B13/D13 -> 0.99797963 | F13: =INDEX($O$8:$O$19, C13) -> 0.98927759 | G13: =B13/F13 -> 573571.18 | K13: =K12+1 -> 6 | L13: Jun | M13: =COUNTIFS(C10:C71,K13,A10:A71,"<=" & $E$3, E10:E71, ">0") -> 3 | N13: =AVERAGEIFS(E10:E71,C10:C71,K13,A10:A71,"<=" & $E$3) -> 0.97268547 | O13: =N13/AVERAGE($N$8:$N$19) -> 0.97911466
A14: 42644 | B14: 623959.57 | C14: =MONTH(A14) -> 10 | D14: =(AVERAGE(B8:B19)+AVERAGE(B9:B20))/2 -> 566104.41 | E14: =B14/D14 -> 1.1021987 | F14: =INDEX($O$8:$O$19, C14) -> 1.004943 | G14: =B14/F14 -> 620890.53 | K14: =K13+1 -> 7 | L14: Jul | M14: =COUNTIFS(C11:C72,K14,A11:A72,"<=" & $E$3, E11:E72, ">0") -> 4 | N14: =AVERAGEIFS(E11:E72,C11:C72,K14,A11:A72,"<=" & $E$3) -> 0.84772928 | O14: =N14/AVERAGE($N$8:$N$19) -> 0.85333255
A15: 42675 | B15: 649949.36 | C15: =MONTH(A15) -> 11 | D15: =(AVERAGE(B9:B20)+AVERAGE(B10:B21))/2 -> 564781.96 | E15: =B15/D15 -> 1.150797 | F15: =INDEX($O$8:$O$19, C15) -> 1.081312 | G15: =B15/F15 -> 601074.77 | K15: =K14+1 -> 8 | L15: Aug | M15: =COUNTIFS(C12:C73,K15,A12:A73,"<=" & $E$3, E12:E73, ">0") -> 3 | N15: =AVERAGEIFS(E12:E73,C12:C73,K15,A12:A73,"<=" & $E$3) -> 0.90494718 | O15: =N15/AVERAGE($N$8:$N$19) -> 0.91092865
A16: 42705 | B16: 998403.46 | C16: =MONTH(A16) -> 12 | D16: =(AVERAGE(B10:B21)+AVERAGE(B11:B22))/2 -> 570341.08 | E16: =B16/D16 -> 1.7505375 | F16: =INDEX($O$8:$O$19, C16) -> 1.6935273 | G16: =B16/F16 -> 589540.81 | K16: =K15+1 -> 9 | L16: Sep | M16: =COUNTIFS(C13:C74,K16,A13:A74,"<=" & $E$3, E13:E74, ">0") -> 3 | N16: =AVERAGEIFS(E13:E74,C13:C74,K16,A13:A74,"<=" & $E$3) -> 0.98278166 | O16: =N16/AVERAGE($N$8:$N$19) -> 0.98927759
A17: 42736 | B17: 670114.8 | C17: =MONTH(A17) -> 1 | D17: =(AVERAGE(B11:B22)+AVERAGE(B12:B23))/2 -> 577423.28 | E17: =B17/D17 -> 1.1605261 | F17: =INDEX($O$8:$O$19, C17) -> 1.2634176 | G17: =B17/F17 -> 530398.52 | K17: =K16+1 -> 10 | L17: Oct | M17: =COUNTIFS(C14:C75,K17,A14:A75,"<=" & $E$3, E14:E75, ">0") -> 3 | N17: =AVERAGEIFS(E14:E75,C14:C75,K17,A14:A75,"<=" & $E$3) -> 0.99834418 | O17: =N17/AVERAGE($N$8:$N$19) -> 1.004943
A18: 42767 | B18: 750526.19 | C18: =MONTH(A18) -> 2 | D18: =(AVERAGE(B12:B23)+AVERAGE(B13:B24))/2 -> 581702.17 | E18: =B18/D18 -> 1.2902242 | F18: =INDEX($O$8:$O$19, C18) -> 1.4898148 | G18: =B18/F18 -> 503771.47 | K18: =K17+1 -> 11 | L18: Nov | M18: =COUNTIFS(C15:C76,K18,A15:A76,"<=" & $E$3, E15:E76, ">0") -> 3 | N18: =AVERAGEIFS(E15:E76,C15:C76,K18,A15:A76,"<=" & $E$3) -> 1.0742117 | O18: =N18/AVERAGE($N$8:$N$19) -> 1.081312
A19: 42795 | B19: 331248.59 | C19: =MONTH(A19) -> 3 | D19: =(AVERAGE(B13:B24)+AVERAGE(B14:B25))/2 -> 588569.68 | E19: =B19/D19 -> 0.56280267 | F19: =INDEX($O$8:$O$19, C19) -> 0.55770218 | G19: =B19/F19 -> 593952.48 | K19: =K18+1 -> 12 | L19: Dec | M19: =COUNTIFS(C16:C77,K19,A16:A77,"<=" & $E$3, E16:E77, ">0") -> 3 | N19: =AVERAGEIFS(E16:E77,C16:C77,K19,A16:A77,"<=" & $E$3) -> 1.682407 | O19: =N19/AVERAGE($N$8:$N$19) -> 1.6935273
A20: 42826 | B20: 58580.07 | C20: =MONTH(A20) -> 4 | D20: =(AVERAGE(B14:B25)+AVERAGE(B15:B26))/2 -> 593716.17 | E20: =B20/D20 -> 0.098666791 | F20: =INDEX($O$8:$O$19, C20) -> 0.093836862 | G20: =B20/F20 -> 624275.67 | J20: Check Sum: | K20: =COUNT(K8:K19) -> 12 | O20: =SUM(O8:O19) -> 12
A21: 42856 | B21: 616258.96 | C21: =MONTH(A21) -> 5 | D21: =(AVERAGE(B15:B26)+AVERAGE(B16:B27))/2 -> 594146.82 | E21: =B21/D21 -> 1.0372166 | F21: =INDEX($O$8:$O$19, C21) -> 1.0827929 | G21: =B21/F21 -> 569138.35
A22: 42887 | B22: 631731.3 | C22: =MONTH(A22) -> 6 | D22: =(AVERAGE(B16:B27)+AVERAGE(B17:B28))/2 -> 606419.62 | E22: =B22/D22 -> 1.0417395 | F22: =INDEX($O$8:$O$19, C22) -> 0.97911466 | G22: =B22/F22 -> 645206.66 | K22: Current Level: | M22: =AVERAGE(G64:G66) -> 381339.14 | O22: Average revenue for the Last 3 months (Dec 2020 - Feb 2021)
A23: 42917 | B23: 511786.72 | C23: =MONTH(A23) -> 7 | D23: =(AVERAGE(B17:B28)+AVERAGE(B18:B29))/2 -> 628741.88 | E23: =B23/D23 -> 0.81398542 | F23: =INDEX($O$8:$O$19, C23) -> 0.85333255 | G23: =B23/F23 -> 599750.61 | K23: Last month: | M23: 44228
A24: 42948 | B24: 593379.05 | C24: =MONTH(A24) -> 8 | D24: =(AVERAGE(B18:B29)+AVERAGE(B19:B30))/2 -> 663774.26 | E24: =B24/D24 -> 0.89394707 | F24: =INDEX($O$8:$O$19, C24) -> 0.91092865 | G24: =B24/F24 -> 651400.14
A25: 42979 | B25: 686375.1 | C25: =MONTH(A25) -> 9 | D25: =(AVERAGE(B19:B30)+AVERAGE(B20:B31))/2 -> 692837.55 | E25: =B25/D25 -> 0.99067249 | F25: =INDEX($O$8:$O$19, C25) -> 0.98927759 | G25: =B25/F25 -> 693814.46
A26: 43009 | B26: 628521.43 | C26: =MONTH(A26) -> 10 | D26: =(AVERAGE(B20:B31)+AVERAGE(B21:B32))/2 -> 697660.47 | E26: =B26/D26 -> 0.90089873 | F26: =INDEX($O$8:$O$19, C26) -> 1.004943 | G26: =B26/F26 -> 625429.95
A27: 43040 | B27: 655722.99 | C27: =MONTH(A27) -> 11 | D27: =(AVERAGE(B21:B32)+AVERAGE(B22:B33))/2 -> 717204.39 | E27: =B27/D27 -> 0.91427632 | F27: =INDEX($O$8:$O$19, C27) -> 1.081312 | G27: =B27/F27 -> 606414.24
A28: 43070 | B28: 1287177.1 | C28: =MONTH(A28) -> 12 | D28: =(AVERAGE(B22:B33)+AVERAGE(B23:B34))/2 -> 750506.5 | E28: =B28/D28 -> 1.7150778 | F28: =INDEX($O$8:$O$19, C28) -> 1.6935273 | G28: =B28/F28 -> 760056.88
A29: 43101 | B29: 917075.35 | C29: =MONTH(A29) -> 1 | D29: =(AVERAGE(B23:B34)+AVERAGE(B24:B35))/2 -> 783615.11 | E29: =B29/D29 -> 1.1703135 | F29: =INDEX($O$8:$O$19, C29) -> 1.2634176 | G29: =B29/F29 -> 725868.77
A30: 43132 | B30: 1344342.7 | C30: =MONTH(A30) -> 2 | D30: =(AVERAGE(B24:B35)+AVERAGE(B25:B36))/2 -> 820524.67 | E30: =B30/D30 -> 1.638394 | F30: =INDEX($O$8:$O$19, C30) -> 1.4898148 | G30: =B30/F30 -> 902355.59
A31: 43160 | B31: 434951.15 | C31: =MONTH(A31) -> 3 | D31: =(AVERAGE(B25:B36)+AVERAGE(B26:B37))/2 -> 859227.04 | E31: =B31/D31 -> 0.50621213 | F31: =INDEX($O$8:$O$19, C31) -> 0.55770218 | G31: =B31/F31 -> 779898.6
A32: 43191 | B32: 70627.54 | C32: =MONTH(A32) -> 4 | D32: =(AVERAGE(B26:B37)+AVERAGE(B27:B38))/2 -> 905418.65 | E32: =B32/D32 -> 0.078005396 | F32: =INDEX($O$8:$O$19, C32) -> 0.093836862 | G32: =B32/F32 -> 752663.06
A33: 43221 | B33: 1073265.6 | C33: =MONTH(A33) -> 5 | D33: =(AVERAGE(B27:B38)+AVERAGE(B28:B39))/2 -> 965231.66 | E33: =B33/D33 -> 1.1119254 | F33: =INDEX($O$8:$O$19, C33) -> 1.0827929 | G33: =B33/F33 -> 991201.15
A34: 43252 | B34: 973975.33 | C34: =MONTH(A34) -> 6 | D34: =(AVERAGE(B28:B39)+AVERAGE(B29:B40))/2 -> 1032620.5 | E34: =B34/D34 -> 0.94320742 | F34: =INDEX($O$8:$O$19, C34) -> 0.97911466 | G34: =B34/F34 -> 994751.04
A35: 43282 | B35: 964149.46 | C35: =MONTH(A35) -> 7 | D35: =(AVERAGE(B29:B40)+AVERAGE(B30:B41))/2 -> 1108406.1 | E35: =B35/D35 -> 0.86985221 | F35: =INDEX($O$8:$O$19, C35) -> 0.85333255 | G35: =B35/F35 -> 1129863.7
... A60: 44044 | B60: 416647.08 | C60: =MONTH(A60) -> 8 | D60: =(AVERAGE(B54:B65)+AVERAGE(B55:B66))/2 -> 574012.19 | E60: =B60/D60 -> 0.72585058 | F60: =INDEX($O$8:$O$19, C60) -> 0.91092865 | G60: =B60/F60 -> 457387.18
A61: 44075 | B61: 380431.52 | C61: =MONTH(A61) -> 9 | F61: =INDEX($O$8:$O$19, C61) -> 0.98927759 | G61: =B61/F61 -> 384554.87
A62: 44105 | B62: 245647.59 | C62: =MONTH(A62) -> 10 | F62: =INDEX($O$8:$O$19, C62) -> 1.004943 | G62: =B62/F62 -> 244439.33
A63: 44136 | B63: 256701.02 | C63: =MONTH(A63) -> 11 | F63: =INDEX($O$8:$O$19, C63) -> 1.081312 | G63: =B63/F63 -> 237397.74
A64: 44166 | B64: 651526.44 | C64: =MONTH(A64) -> 12 | F64: =INDEX($O$8:$O$19, C64) -> 1.6935273 | G64: =B64/F64 -> 384715.64
...

Sheet Forecast Sheet
A1: Excel Forecast.ETS
A2: Here are the results using the built-in Excel forecast function.
A4: Timeline | B4: Values | C4: Forecast | D4: Lower Confidence Bound | E4: Upper Confidence Bound | G4: Statistic | H4: Value
A5: 1 | B5: 649918.78 | G5: Alpha | H5: =_xlfn.FORECAST.ETS.STAT($B$5:$B$66,$A$5:$A$66,1,1,1) -> 0.002
A6: 2 | B6: 891098.3 | G6: Beta | H6: =_xlfn.FORECAST.ETS.STAT($B$5:$B$66,$A$5:$A$66,2,1,1) -> 0.001
A7: 3 | B7: 338407.36 | G7: Gamma | H7: =_xlfn.FORECAST.ETS.STAT($B$5:$B$66,$A$5:$A$66,3,1,1) -> 2.220446e-16
A8: 4 | B8: 110591.63 | G8: MASE | H8: =_xlfn.FORECAST.ETS.STAT($B$5:$B$66,$A$5:$A$66,4,1,1) -> 2.264733
A9: 5 | B9: 595986.18 | G9: SMAPE | H9: =_xlfn.FORECAST.ETS.STAT($B$5:$B$66,$A$5:$A$66,5,1,1) -> 0.81410632
A10: 6 | B10: 518585.28 | G10: MAE | H10: =_xlfn.FORECAST.ETS.STAT($B$5:$B$66,$A$5:$A$66,6,1,1) -> 686423.71
A11: 7 | B11: 454959.83 | G11: RMSE | H11: =_xlfn.FORECAST.ETS.STAT($B$5:$B$66,$A$5:$A$66,7,1,1) -> 731288.84
A12: 8 | B12: 547512.69
A13: 9 | B13: 567421.12
A14: 10 | B14: 623959.57
A15: 11 | B15: 649949.36
A16: 12 | B16: 998403.46
A17: 13 | B17: 670114.8
A18: 14 | B18: 750526.19
A19: 15 | B19: 331248.59
A20: 16 | B20: 58580.07
A21: 17 | B21: 616258.96
A22: 18 | B22: 631731.3
A23: 19 | B23: 511786.72
... A65: 61 | B65: 513021.58
A66: 62 | B66: 526266.9 | C66: 526266.9 | D66: 526266.9 | E66: 526266.9
A67: 63 | C67: =_xlfn.FORECAST.ETS(A67,$B$5:$B$66,$A$5:$A$66,1,1) -> 1218834.4 | D67: =C67-_xlfn.FORECAST.ETS.CONFINT(A67,$B$5:$B$66,$A$5:$A$66,0.95,1,1) -> 85934.483 | E67: =C67+_xlfn.FORECAST.ETS.CONFINT(A67,$B$5:$B$66,$A$5:$A$66,0.95,1,1) -> 2351734.3
A68: 64 | C68: =_xlfn.FORECAST.ETS(A68,$B$5:$B$66,$A$5:$A$66,1,1) -> 1228354.7 | D68: =C68-_xlfn.FORECAST.ETS.CONFINT(A68,$B$5:$B$66,$A$5:$A$66,0.95,1,1) -> 95449.678 | E68: =C68+_xlfn.FORECAST.ETS.CONFINT(A68,$B$5:$B$66,$A$5:$A$66,0.95,1,1) -> 2361259.7
A69: 65 | C69: =_xlfn.FORECAST.ETS(A69,$B$5:$B$66,$A$5:$A$66,1,1) -> 1237875 | D69: =C69-_xlfn.FORECAST.ETS.CONFINT(A69,$B$5:$B$66,$A$5:$A$66,0.95,1,1) -> 104960.91 | E69: =C69+_xlfn.FORECAST.ETS.CONFINT(A69,$B$5:$B$66,$A$5:$A$66,0.95,1,1) -> 2370789
A70: 66 | C70: =_xlfn.FORECAST.ETS(A70,$B$5:$B$66,$A$5:$A$66,1,1) -> 1247395.3 | D70: =C70-_xlfn.FORECAST.ETS.CONFINT(A70,$B$5:$B$66,$A$5:$A$66,0.95,1,1) -> 114467.04 | E70: =C70+_xlfn.FORECAST.ETS.CONFINT(A70,$B$5:$B$66,$A$5:$A$66,0.95,1,1) -> 2380323.5
A71: 67 | C71: =_xlfn.FORECAST.ETS(A71,$B$5:$B$66,$A$5:$A$66,1,1) -> 1256915.5 | D71: =C71-_xlfn.FORECAST.ETS.CONFINT(A71,$B$5:$B$66,$A$5:$A$66,0.95,1,1) -> 123966.94 | E71: =C71+_xlfn.FORECAST.ETS.CONFINT(A71,$B$5:$B$66,$A$5:$A$66,0.95,1,1) -> 2389864.1
A72: 68 | C72: =_xlfn.FORECAST.ETS(A72,$B$5:$B$66,$A$5:$A$66,1,1) -> 1266435.8 | D72: =C72-_xlfn.FORECAST.ETS.CONFINT(A72,$B$5:$B$66,$A$5:$A$66,0.95,1,1) -> 133459.48 | E72: =C72+_xlfn.FORECAST.ETS.CONFINT(A72,$B$5:$B$66,$A$5:$A$66,0.95,1,1) -> 2399412.2
A73: 69 | C73: =_xlfn.FORECAST.ETS(A73,$B$5:$B$66,$A$5:$A$66,1,1) -> 1275956.1 | D73: =C73-_xlfn.FORECAST.ETS.CONFINT(A73,$B$5:$B$66,$A$5:$A$66,0.95,1,1) -> 142943.52 | E73: =C73+_xlfn.FORECAST.ETS.CONFINT(A73,$B$5:$B$66,$A$5:$A$66,0.95,1,1) -> 2408968.7
A74: 70 | C74: =_xlfn.FORECAST.ETS(A74,$B$5:$B$66,$A$5:$A$66,1,1) -> 1285476.4 | D74: =C74-_xlfn.FORECAST.ETS.CONFINT(A74,$B$5:$B$66,$A$5:$A$66,0.95,1,1) -> 152417.94 | E74: =C74+_xlfn.FORECAST.ETS.CONFINT(A74,$B$5:$B$66,$A$5:$A$66,0.95,1,1) -> 2418534.9
A75: 71 | C75: =_xlfn.FORECAST.ETS(A75,$B$5:$B$66,$A$5:$A$66,1,1) -> 1294996.7 | D75: =C75-_xlfn.FORECAST.ETS.CONFINT(A75,$B$5:$B$66,$A$5:$A$66,0.95,1,1) -> 161881.6 | E75: =C75+_xlfn.FORECAST.ETS.CONFINT(A75,$B$5:$B$66,$A$5:$A$66,0.95,1,1) -> 2428111.8
A76: 72 | C76: =_xlfn.FORECAST.ETS(A76,$B$5:$B$66,$A$5:$A$66,1,1) -> 1304517 | D76: =C76-_xlfn.FORECAST.ETS.CONFINT(A76,$B$5:$B$66,$A$5:$A$66,0.95,1,1) -> 171333.37 | E76: =C76+_xlfn.FORECAST.ETS.CONFINT(A76,$B$5:$B$66,$A$5:$A$66,0.95,1,1) -> 2437700.7
A77: 73 | C77: =_xlfn.FORECAST.ETS(A77,$B$5:$B$66,$A$5:$A$66,1,1) -> 1314037.3 | D77: =C77-_xlfn.FORECAST.ETS.CONFINT(A77,$B$5:$B$66,$A$5:$A$66,0.95,1,1) -> 180772.11 | E77: =C77+_xlfn.FORECAST.ETS.CONFINT(A77,$B$5:$B$66,$A$5:$A$66,0.95,1,1) -> 2447302.5
A78: 74 | C78: =_xlfn.FORECAST.ETS(A78,$B$5:$B$66,$A$5:$A$66,1,1) -> 1323557.6 | D78: =C78-_xlfn.FORECAST.ETS.CONFINT(A78,$B$5:$B$66,$A$5:$A$66,0.95,1,1) -> 190196.71 | E78: =C78+_xlfn.FORECAST.ETS.CONFINT(A78,$B$5:$B$66,$A$5:$A$66,0.95,1,1) -> 2456918.5
A81: Month | B81: Lower Bound (USD) | C81: Forecast (USD) | D81: Upper Bound (USD)
A82: 44256 | B82: =D67*$D$97 -> 53857.528 | C82: =C67*$D$97 -> 763877.37 | D82: =E67*$D$97 -> 1473897.2
A83: 44287 | B83: =D68*$D$97 -> 59820.966 | C83: =C68*$D$97 -> 769844 | D83: =E68*$D$97 -> 1479867
A84: 44317 | B84: =D69*$D$97 -> 65781.918 | C84: =C69*$D$97 -> 775810.63 | D84: =E69*$D$97 -> 1485839.3
...

Sheet Data
A1: Monthly Revenue: January 2016 to February 2021
A2: Reference: ge.vw_sales_products_fact
A4: Month | B4: Series | C4: Revenue | D4: MoM_Change_USD | E4: MoM_Change_%
A5: 42370 | B5: =MONTH(ge_vw_revenue_forecast[[#This Row],[Month]]) -> 1 | C5: 649918.78
A6: 42401 | B6: 2 | C6: 891098.3 | D6: 649918.78 | E6: 37.11
A7: 42430 | B7: 3 | C7: 338407.36 | D7: 891098.3 | E7: -62.02
A8: 42461 | B8: 4 | C8: 110591.63 | D8: 338407.36 | E8: -67.32
A9: 42491 | B9: 5 | C9: 595986.18 | D9: 110591.63 | E9: 438.91
A10: 42522 | B10: 6 | C10: 518585.28 | D10: 595986.18 | E10: -12.99
A11: 42552 | B11: 7 | C11: 454959.83 | D11: 518585.28 | E11: -12.27
A12: 42583 | B12: 8 | C12: 547512.69 | D12: 454959.83 | E12: 20.34 | H12: s
A13: 42614 | B13: 9 | C13: 567421.12 | D13: 547512.69 | E13: 3.64
A14: 42644 | B14: 10 | C14: 623959.57 | D14: 567421.12 | E14: 9.96
A15: 42675 | B15: 11 | C15: 649949.36 | D15: 623959.57 | E15: 4.17
A16: 42705 | B16: 12 | C16: 998403.46 | D16: 649949.36 | E16: 53.61
A17: 42736 | B17: 13 | C17: 670114.8 | D17: 998403.46 | E17: -32.88
A18: 42767 | B18: 14 | C18: 750526.19 | D18: 670114.8 | E18: 12
A19: 42795 | B19: 15 | C19: 331248.59 | D19: 750526.19 | E19: -55.86
A20: 42826 | B20: 16 | C20: 58580.07 | D20: 331248.59 | E20: -82.32
A21: 42856 | B21: 17 | C21: 616258.96 | D21: 58580.07 | E21: 951.99
A22: 42887 | B22: 18 | C22: 631731.3 | D22: 616258.96 | E22: 2.51
A23: 42917 | B23: 19 | C23: 511786.72 | D23: 631731.3 | E23: -18.99
A24: 42948 | B24: 20 | C24: 593379.05 | D24: 511786.72 | E24: 15.94
... A66: 44228 | B66: 62 | C66: 526266.9 | D66: 513021.58 | E66: 2.58
